{"trial_id": "0038", "hyperparameters": {"space": [{"class_name": "Choice", "config": {"name": "optimizer", "default": "rmsprop", "conditions": [], "values": ["rmsprop", "adam", "sgd", "nadam"], "ordered": false}}, {"class_name": "Choice", "config": {"name": "loss", "default": "mse", "conditions": [], "values": ["mse", "mae", "rmse"], "ordered": false}}, {"class_name": "Int", "config": {"name": "lstm_units", "default": null, "conditions": [], "min_value": 32, "max_value": 128, "step": 32, "sampling": "linear"}}, {"class_name": "Int", "config": {"name": "dense_units", "default": null, "conditions": [], "min_value": 32, "max_value": 128, "step": 32, "sampling": "linear"}}], "values": {"optimizer": "adam", "loss": "rmse", "lstm_units": 96, "dense_units": 96, "tuner/epochs": 6, "tuner/initial_epoch": 0, "tuner/bracket": 2, "tuner/round": 0}}, "metrics": {"metrics": {}}, "score": null, "best_step": 0, "status": "FAILED", "message": "Traceback (most recent call last):\n  File \"c:\\Python311\\Lib\\site-packages\\keras_tuner\\src\\engine\\base_tuner.py\", line 274, in _try_run_and_update_trial\n    self._run_and_update_trial(trial, *fit_args, **fit_kwargs)\n  File \"c:\\Python311\\Lib\\site-packages\\keras_tuner\\src\\engine\\base_tuner.py\", line 239, in _run_and_update_trial\n    results = self.run_trial(trial, *fit_args, **fit_kwargs)\n              ^^^^^^^^^^^^^^^^^^^^^^^^^^^^^^^^^^^^^^^^^^^^^^\n  File \"c:\\Python311\\Lib\\site-packages\\keras_tuner\\src\\tuners\\hyperband.py\", line 427, in run_trial\n    return super().run_trial(trial, *fit_args, **fit_kwargs)\n           ^^^^^^^^^^^^^^^^^^^^^^^^^^^^^^^^^^^^^^^^^^^^^^^^^\n  File \"c:\\Python311\\Lib\\site-packages\\keras_tuner\\src\\engine\\tuner.py\", line 314, in run_trial\n    obj_value = self._build_and_fit_model(trial, *args, **copied_kwargs)\n                ^^^^^^^^^^^^^^^^^^^^^^^^^^^^^^^^^^^^^^^^^^^^^^^^^^^^^^^^\n  File \"c:\\Python311\\Lib\\site-packages\\keras_tuner\\src\\engine\\tuner.py\", line 233, in _build_and_fit_model\n    results = self.hypermodel.fit(hp, model, *args, **kwargs)\n              ^^^^^^^^^^^^^^^^^^^^^^^^^^^^^^^^^^^^^^^^^^^^^^^\n  File \"c:\\Python311\\Lib\\site-packages\\keras_tuner\\src\\engine\\hypermodel.py\", line 149, in fit\n    return model.fit(*args, **kwargs)\n           ^^^^^^^^^^^^^^^^^^^^^^^^^^\n  File \"c:\\Python311\\Lib\\site-packages\\keras\\src\\utils\\traceback_utils.py\", line 70, in error_handler\n    raise e.with_traceback(filtered_tb) from None\n  File \"C:\\Users\\Alon\\AppData\\Local\\Temp\\__autograph_generated_file6x96gzgu.py\", line 18, in tf__train_function\n    raise\nValueError: in user code:\n\n    File \"c:\\Python311\\Lib\\site-packages\\keras\\src\\engine\\training.py\", line 1401, in train_function  *\n        return step_function(self, iterator)\n    File \"c:\\Python311\\Lib\\site-packages\\keras\\src\\engine\\training.py\", line 1384, in step_function  **\n        outputs = model.distribute_strategy.run(run_step, args=(data,))\n    File \"c:\\Python311\\Lib\\site-packages\\keras\\src\\engine\\training.py\", line 1373, in run_step  **\n        outputs = model.train_step(data)\n    File \"c:\\Python311\\Lib\\site-packages\\keras\\src\\engine\\training.py\", line 1151, in train_step\n        loss = self.compute_loss(x, y, y_pred, sample_weight)\n    File \"c:\\Python311\\Lib\\site-packages\\keras\\src\\engine\\training.py\", line 1209, in compute_loss\n        return self.compiled_loss(\n    File \"c:\\Python311\\Lib\\site-packages\\keras\\src\\engine\\compile_utils.py\", line 252, in __call__\n        self.build(y_pred)\n    File \"c:\\Python311\\Lib\\site-packages\\keras\\src\\engine\\compile_utils.py\", line 194, in build\n        self._losses = tf.nest.map_structure(\n    File \"c:\\Python311\\Lib\\site-packages\\keras\\src\\engine\\compile_utils.py\", line 365, in _get_loss_object\n        loss = losses_mod.get(loss)\n    File \"c:\\Python311\\Lib\\site-packages\\keras\\src\\losses.py\", line 2965, in get\n        return deserialize(identifier, use_legacy_format=use_legacy_format)\n    File \"c:\\Python311\\Lib\\site-packages\\keras\\src\\losses.py\", line 2912, in deserialize\n        return legacy_serialization.deserialize_keras_object(\n    File \"c:\\Python311\\Lib\\site-packages\\keras\\src\\saving\\legacy\\serialization.py\", line 537, in deserialize_keras_object\n        raise ValueError(\n\n    ValueError: Unknown loss function: 'rmse'. Please ensure you are using a `keras.utils.custom_object_scope` and that this object is included in the scope. See https://www.tensorflow.org/guide/keras/save_and_serialize#registering_the_custom_object for details.\n\n"}